Workbook

Sheet Rules
A2: 1 | B2: Banchmark & Universe
B3: a | C3: Banchmark | D3: S&P 500
B4: b | C4: Universe | D4: S&P 300
A5: 2 | B5: Parameter
B6: a | C6: Holding & Review | D6: Monthly
B7: b | C7: Number of stocks | D7: 10-16
B8: c | C8: Weighted Limit | D8: Max 12-15% per stock, sector cap 30%
B9: d | C9: Rebalancing | D9: Monthly
A10: 3 | B10: Data
B11: a | C11: Monthly Price (close) | D11: Min 5-10 years
B12: b | C12: Risk-Free | D12: T-Bill 3 Month

Sheet Summary
A1: No | B1: Date | C1: Balance | D1: % Change
A2: 1 | B2: 45292 | C2: ='2024'!H114 -> 9799 | D2: 0
A3: 2 | B3: 45323 | C3: ='2024'!J114 -> 10166.629 | D3: =(C3-C2)/C2 -> 0.037517009
A4: 3 | B4: 45352 | C4: ='2024'!L114 -> 10812.168 | D4: =(C4-C3)/C3 -> 0.063495814
A5: 4 | B5: 45383 | C5: ='2024'!N114 -> 10970.92 | D5: =(C5-C4)/C4 -> 0.014682727
A6: 5 | B6: 45413 | C6: ='2024'!P114 -> 10264.146 | D6: =(C6-C5)/C5 -> -0.06442245
A7: 6 | B7: 45444 | C7: ='2024'!R114 -> 10967.639 | D7: =(C7-C6)/C6 -> 0.068538818
A8: 7 | B8: 45474 | C8: ='2024'!T114 -> 11410.858 | D8: =(C8-C7)/C7 -> 0.040411523
A9: 8 | B9: 45505 | C9: ='2024'!V114 -> 10835.091 | D9: =(C9-C8)/C8 -> -0.050457799
A10: 9 | B10: 45536 | C10: ='2024'!X114 -> 11720.464 | D10: =(C10-C9)/C9 -> 0.081713459
A11: 10 | B11: 45566 | C11: ='2024'!Z114 -> 11947.281 | D11: =(C11-C10)/C10 -> 0.019352291
A12: 11 | B12: 45597 | C12: ='2024'!AB114 -> 11701.669 | D12: =(C12-C11)/C11 -> -0.020558027
A13: 12 | B13: 45627 | C13: ='2024'!AD114 -> 12497.176 | D13: =(C13-C12)/C12 -> 0.067982381
C15: Annual Return | D15: =(C13-C2)/C2 -> 0.27535219
C16: Average | D16: =AVERAGE(D2:D13) -> 0.021521312
C17: Volatility | D17: ='2024'!H118 -> 0.045205784

Sheet Universe
A1: No | B1: Index | C1: Ticker | D1: Company | E1: Sector | F1: Market Cap (B)
A2: 1 | B2: S&P 500 | C2: NVDA | D2: NVIDIA Corporation | E2: Information Technology | F2: 4150
A3: 2 | B3: S&P 500 | C3: AAPL | D3: Apple Inc. | E3: Information Technology | F3: 4020
A4: 3 | B4: S&P 500 | C4: GOOG | D4: Alphabet Inc. | E4: Information Technology | F4: 3710
A5: 4 | B5: S&P 500 | C5: GOOGL | D5: Alphabet Inc. | E5: Information Technology | F5: 3580
A6: 5 | B6: S&P 500 | C6: MSFT | D6: Microsoft Corporation | E6: Information Technology | F6: 3540
A7: 6 | B7: S&P 500 | C7: AMZN | D7: Amazon.com Inc. | E7: Consumer Discretionary | F7: 2370
A8: 7 | B8: S&P 500 | C8: META | D8: Meta Platforms Inc. | E8: Information Technology | F8: 1640
A9: 8 | B9: S&P 500 | C9: TSLA | D9: Tesla Inc. | E9: Consumer Discretionary | F9: 1550
A10: 9 | B10: S&P 500 | C10: AVGO | D10: Broadcom Inc. | E10: Information Technology | F10: 1540
A11: 10 | B11: S&P 500 | C11: BRK.B | D11: Berkshire Hathaway Inc. | E11: Financials | F11: 1090
A12: 11 | B12: S&P 500 | C12: LLY | D12: Eli Lilly and Company | E12: Health Care | F12: 933
A13: 12 | B13: S&P 500 | C13: WMT | D13: Walmart Inc. | E13: Consumer Staples | F13: 922
... A201: 200 | B201: S&P 500 | C201: RCL | D201: Royal Caribbean | E201: Consumer Discretionary | F201: 24

Sheet 2024
A1: Balance | B1: 10000
A2: No | B2: Sector | C2: Ticker | D2: Company | E2: Div % | F2: Number of Stock | G2: Price Buy | H2: January (1) | I2: Price Feb | J2: February (2) | K2: Price Mar | L2: March (3) | M2: Price Apr | N2: April (4) | O2: Price May | P2: May (5) | Q2: Price Jun | R2: June (6) | S2: Price Jul | T2: July (7) | U2: Price Aug | V2: August (8) | W2: Price Sep | X2: September (9) | Y2: Price Oct | Z2: Oktober (10) | AA2: Price Nov | AB2: November (11) | AC2: Price Dec | AD2: Desember (12)
A3: ROUND 1
A4: 1 | B4: =VLOOKUP(C4,Universe!$C$2:$E$201,3,FALSE) -> Information Technology | C4: INTC | D4: =VLOOKUP(C4,Universe!$C$2:$D$201,2,FALSE) -> Intel Corp. | E4: 0.15 | F4: =($B$1*E4)/G4 -> 30.248034 | G4: 49.59 | H4: =F4*G4 -> 1500 | I4: 42.79 | J4: =F4*I4 -> 1294.3134 | K4: 43.37 | L4: =F4*K4 -> 1311.8572
A5: 2 | B5: =VLOOKUP(C5,Universe!$C$2:$E$201,3,FALSE) -> Health Care | C5: LLY | D5: =VLOOKUP(C5,Universe!$C$2:$D$201,2,FALSE) -> Eli Lilly and Company | E5: 0.15 | F5: =($B$1*E5)/G5 -> 2.6093764 | G5: 574.85 | H5: =F5*G5 -> 1500 | I5: 651.29 | J5: =F5*I5 -> 1699.4607 | K5: 772.65 | L5: =F5*K5 -> 2016.1346
A6: 3 | B6: =VLOOKUP(C6,Universe!$C$2:$E$201,3,FALSE) -> Consumer Discretionary | C6: BKNG | D6: =VLOOKUP(C6,Universe!$C$2:$D$201,2,FALSE) -> Booking Holdings | E6: 0.15 | F6: =($B$1*E6)/G6 -> 0.42978588 | G6: 3490.11 | H6: =F6*G6 -> 1500 | I6: 3501.16 | J6: =F6*I6 -> 1504.7491 | K6: 3443.39 | L6: =F6*K6 -> 1479.9204
A7: 4 | B7: =VLOOKUP(C7,Universe!$C$2:$E$201,3,FALSE) -> Consumer Discretionary | C7: AMZN | D7: =VLOOKUP(C7,Universe!$C$2:$D$201,2,FALSE) -> Amazon.com Inc. | E7: 0.1 | F7: =($B$1*E7)/G7 -> 6.5815453 | G7: 151.94 | H7: =F7*G7 -> 1000 | I7: 159.28 | J7: =F7*I7 -> 1048.3085 | K7: 178.22 | L7: =F7*K7 -> 1172.963
A8: 5 | B8: =VLOOKUP(C8,Universe!$C$2:$E$201,3,FALSE) -> Information Technology | C8: WDAY | D8: =VLOOKUP(C8,Universe!$C$2:$D$201,2,FALSE) -> Workday Inc. | E8: 0.1083 | F8: =($B$1*E8)/G8 -> 3.9230602 | G8: 276.06 | H8: =F8*G8 -> 1083 | I8: 294 | J8: =F8*I8 -> 1153.3797 | K8: 291.92 | L8: =F8*K8 -> 1145.2197
A9: 6 | B9: =VLOOKUP(C9,Universe!$C$2:$E$201,3,FALSE) -> Information Technology | C9: STX | D9: =VLOOKUP(C9,Universe!$C$2:$D$201,2,FALSE) -> Seagate Tech. | E9: 0.0694 | F9: =($B$1*E9)/G9 -> 8.506987 | G9: 81.58 | H9: =F9*G9 -> 694 | I9: 82.94 | J9: =F9*I9 -> 705.5695 | K9: 92.84 | L9: =F9*K9 -> 789.78867
A10: 7 | B10: =VLOOKUP(C10,Universe!$C$2:$E$201,3,FALSE) -> Information Technology | C10: TEAM | D10: =VLOOKUP(C10,Universe!$C$2:$D$201,2,FALSE) -> Atlassian Corp. | E10: 0.0969 | F10: =($B$1*E10)/G10 -> 4.0738249 | G10: 237.86 | H10: =F10*G10 -> 969 | I10: 254.9 | J10: =F10*I10 -> 1038.418 | K10: 209.2 | L10: =F10*K10 -> 852.24418
A11: 8 | B11: =VLOOKUP(C11,Universe!$C$2:$E$201,3,FALSE) -> Information Technology | C11: META | D11: =VLOOKUP(C11,Universe!$C$2:$D$201,2,FALSE) -> Meta Platforms Inc. | E11: 0.0654 | F11: =($B$1*E11)/G11 -> 1.8605974 | G11: 351.5 | H11: =F11*G11 -> 654 | I11: 392.04 | J11: =F11*I11 -> 729.42862 | K11: 499.34 | L11: =F11*K11 -> 929.07073
A12: 9 | B12: =VLOOKUP(C12,Universe!$C$2:$E$201,3,FALSE) -> Consumer Discretionary | C12: NFLX | D12: =VLOOKUP(C12,Universe!$C$2:$D$201,2,FALSE) -> Netflix Inc. | E12: 0.0293 | F12: =($B$1*E12)/G12 -> 6.0176628 | G12: 48.69 | H12: =F12*G12 -> 293 | I12: 56.75 | J12: =F12*I12 -> 341.50236 | K12: 61.93 | L12: =F12*K12 -> 372.67386
A13: 10 | B13: =VLOOKUP(C13,Universe!$C$2:$E$201,3,FALSE) -> Industrials | C13: GE | D13: =VLOOKUP(C13,Universe!$C$2:$D$201,2,FALSE) -> GE Aerospace | E13: 0.027 | F13: =($B$1*E13)/G13 -> 2.6804328 | G13: 100.73 | H13: =F13*G13 -> 270 | I13: 106.87 | J13: =F13*I13 -> 286.45786 | K13: 125.22 | L13: =F13*K13 -> 335.6438
A14: 11 | B14: =VLOOKUP(C14,Universe!$C$2:$E$201,3,FALSE) -> Information Technology | C14: CRM | D14: =VLOOKUP(C14,Universe!$C$2:$D$201,2,FALSE) -> Salesforce Inc. | E14: 0.0204 | F14: =($B$1*E14)/G14 -> 0.78341014 | G14: 260.4 | H14: =F14*G14 -> 204 | I14: 280.85 | J14: =F14*I14 -> 220.02074 | K14: 313.58 | L14: =F14*K14 -> 245.66175
A15: 12 | B15: =VLOOKUP(C15,Universe!$C$2:$E$201,3,FALSE) -> Industrials | C15: ETN | D15: =VLOOKUP(C15,Universe!$C$2:$D$201,2,FALSE) -> Eaton Corp | E15: 0.0132 | F15: =($B$1*E15)/G15 -> 0.56050955 | G15: 235.5 | H15: =F15*G15 -> 132 | I15: 258.73 | J15: =F15*I15 -> 145.02064 | K15: 287.22 | L15: =F15*K15 -> 160.98955
F16: Total | H16: =SUM(H4:H15) -> 9799 | J16: =SUM(J4:J15) -> 10166.629 | L16: =SUM(L4:L15) -> 10812.168
J17: =(J16-H16)/H16 -> 0.037517009 | L17: =(L16-J16)/J16 -> 0.063495814
A19: ROUND 2 | D19: =SUM(L4:L15) -> 10812.168
A20: 1 | B20: =VLOOKUP(C20,Universe!$C$2:$E$201,3,FALSE) -> Consumer Discretionary | C20: AMZN | D20: =VLOOKUP(C20,Universe!$C$2:$D$201,2,FALSE) -> Amazon.com Inc. | E20: 0.15 | F20: =($D$19*E20)/K20 -> 9.1001298 | K20: 178.22 | L20: =F20*K20 -> 1621.8251 | M20: 180.97 | N20: =F20*M20 -> 1646.8505
A21: 2 | B21: =VLOOKUP(C21,Universe!$C$2:$E$201,3,FALSE) -> Consumer Staples | C21: COST | D21: =VLOOKUP(C21,Universe!$C$2:$D$201,2,FALSE) -> Costco Wholesale Corp | E21: 0.15 | F21: =($D$19*E21)/K21 -> 2.1848354 | K21: 742.31 | L21: =F21*K21 -> 1621.8251 | M21: 714.38 | N21: =F21*M21 -> 1560.8027
A22: 3 | B22: =VLOOKUP(C22,Universe!$C$2:$E$201,3,FALSE) -> Information Technology | C22: INTC | D22: =VLOOKUP(C22,Universe!$C$2:$D$201,2,FALSE) -> Intel Corp. | E22: 0.15 | F22: =($D$19*E22)/K22 -> 37.395092 | K22: 43.37 | L22: =F22*K22 -> 1621.8251 | M22: 44.06 | N22: =F22*M22 -> 1647.6277
A23: 4 | B23: =VLOOKUP(C23,Universe!$C$2:$E$201,3,FALSE) -> Health Care | C23: VRTX | D23: =VLOOKUP(C23,Universe!$C$2:$D$201,2,FALSE) -> Vertex Pharma | E23: 0.15 | F23: =($D$19*E23)/K23 -> 3.7476318 | K23: 432.76 | L23: =F23*K23 -> 1621.8251 | M23: 420.48 | N23: =F23*M23 -> 1575.8042
A24: 5 | B24: =VLOOKUP(C24,Universe!$C$2:$E$201,3,FALSE) -> Financials | C24: PGR | D24: =VLOOKUP(C24,Universe!$C$2:$D$201,2,FALSE) -> Progressive Corp | E24: 0.15 | F24: =($D$19*E24)/K24 -> 8.8228981 | K24: 183.82 | L24: =F24*K24 -> 1621.8251 | M24: 205.47 | N24: =F24*M24 -> 1812.8409
A25: 6 | B25: =VLOOKUP(C25,Universe!$C$2:$E$201,3,FALSE) -> Industrials | C25: GE | D25: =VLOOKUP(C25,Universe!$C$2:$D$201,2,FALSE) -> GE Aerospace | E25: 0.0657 | F25: =($D$19*E25)/K25 -> 5.672891 | K25: 125.22 | L25: =F25*K25 -> 710.35941 | M25: 138.41 | N25: =F25*M25 -> 785.18484
A26: 7 | B26: =VLOOKUP(C26,Universe!$C$2:$E$201,3,FALSE) -> Information Technology | C26: META | D26: =VLOOKUP(C26,Universe!$C$2:$D$201,2,FALSE) -> Meta Platforms Inc. | E26: 0.0493 | F26: =($D$19*E26)/K26 -> 1.0674888 | K26: 499.34 | L26: =F26*K26 -> 533.03986 | M26: 488.46 | N26: =F26*M26 -> 521.42558
A27: 8 | B27: =VLOOKUP(C27,Universe!$C$2:$E$201,3,FALSE) -> Health Care | C27: LLY | D27: =VLOOKUP(C27,Universe!$C$2:$D$201,2,FALSE) -> Eli Lilly and Company | E27: 0.0479 | F27: =($D$19*E27)/K27 -> 0.67029422 | K27: 772.65 | L27: =F27*K27 -> 517.90283 | M27: 751.34 | N27: =F27*M27 -> 503.61886
A28: 9 | B28: =VLOOKUP(C28,Universe!$C$2:$E$201,3,FALSE) -> Information Technology | C28: CRM | D28: =VLOOKUP(C28,Universe!$C$2:$D$201,2,FALSE) -> Salesforce Inc. | E28: 0.0303 | F28: =($D$19*E28)/K28 -> 1.0447372 | K28: 313.58 | L28: =F28*K28 -> 327.60868 | M28: 299.5 | N28: =F28*M28 -> 312.89878
A29: 10 | B29: =VLOOKUP(C29,Universe!$C$2:$E$201,3,FALSE) -> Consumer Discretionary | C29: NFLX | D29: =VLOOKUP(C29,Universe!$C$2:$D$201,2,FALSE) -> Netflix Inc. | E29: 0.0276 | F29: =($D$19*E29)/K29 -> 4.8185988 | K29: 61.93 | L29: =F29*K29 -> 298.41582 | M29: 61.43 | N29: =F29*M29 -> 296.00653
A30: 11 | B30: =VLOOKUP(C30,Universe!$C$2:$E$201,3,FALSE) -> Information Technology | C30: UBER | D30: =VLOOKUP(C30,Universe!$C$2:$D$201,2,FALSE) -> Uber Technologies | E30: 0.0198 | F30: =($D$19*E30)/K30 -> 2.6419958 | K30: 81.03 | L30: =F30*K30 -> 214.08092 | M30: 76.4 | N30: =F30*M30 -> 201.84848
A31: 12 | B31: =VLOOKUP(C31,Universe!$C$2:$E$201,3,FALSE) -> Industrials | C31: ETN | D31: =VLOOKUP(C31,Universe!$C$2:$D$201,2,FALSE) -> Eaton Corp | E31: 0.0092 | F31: =($D$19*E31)/K31 -> 0.34632665 | K31: 287.22 | L31: =F31*K31 -> 99.471942 | M31: 306.1 | N31: =F31*M31 -> 106.01059
L32: =SUM(L20:L31) -> 10810.005 | N32: =SUM(N20:N31) -> 10970.92
N33: =(N32-L32)/L32 -> 0.014885704
A35: ROUND 3 | D35: =N32 -> 10970.92
A36: 1 | B36: =VLOOKUP(C36,Universe!$C$2:$E$201,3,FALSE) -> Financials | C36: AIG | D36: =VLOOKUP(C36,Universe!$C$2:$D$201,2,FALSE) -> AIG | E36: 0.15 | F36: =($D$19*E36)/M36 -> 21.687953 | M36: 74.78 | N36: =F36*M36 -> 1621.8251 | O36: 73.01 | P36: =F36*O36 -> 1583.4375
A37: 2 | B37: =VLOOKUP(C37,Universe!$C$2:$E$201,3,FALSE) -> Health Care | C37: CI | D37: =VLOOKUP(C37,Universe!$C$2:$D$201,2,FALSE) -> The Cigna Group | E37: 0.15 | F37: =($D$19*E37)/M37 -> 4.6017056 | M37: 352.44 | N37: =F37*M37 -> 1621.8251 | O37: 345.76 | P37: =F37*O37 -> 1591.0857
A38: 3 | B38: =VLOOKUP(C38,Universe!$C$2:$E$201,3,FALSE) -> Financials | C38: PGR | D38: =VLOOKUP(C38,Universe!$C$2:$D$201,2,FALSE) -> Progressive Corp | E38: 0.15 | F38: =($D$19*E38)/M38 -> 7.8932454 | M38: 205.47 | N38: =F38*M38 -> 1621.8251 | O38: 207.38 | P38: =F38*O38 -> 1636.9012
A39: 4 | B39: =VLOOKUP(C39,Universe!$C$2:$E$201,3,FALSE) -> Consumer Discretionary | C39: NFLX | D39: =VLOOKUP(C39,Universe!$C$2:$D$201,2,FALSE) -> Netflix Inc. | E39: 0.15 | F39: =($D$19*E39)/M39 -> 26.401191 | M39: 61.43 | N39: =F39*M39 -> 1621.8251 | O39: 55.17 | P39: =F39*O39 -> 1456.5537
A40: 5 | B40: =VLOOKUP(C40,Universe!$C$2:$E$201,3,FALSE) -> Information Technology | C40: IBM | D40: =VLOOKUP(C40,Universe!$C$2:$D$201,2,FALSE) -> IBM Corporation | E40: 0.15 | F40: =($D$19*E40)/M40 -> 8.9991407 | M40: 180.22 | N40: =F40*M40 -> 1621.8251 | O40: 156.11 | P40: =F40*O40 -> 1404.8559
A41: 6 | B41: =VLOOKUP(C41,Universe!$C$2:$E$201,3,FALSE) -> Consumer Discretionary | C41: AMZN | D41: =VLOOKUP(C41,Universe!$C$2:$D$201,2,FALSE) -> Amazon.com Inc. | E41: 0.15 | F41: =($D$19*E41)/M41 -> 8.9618452 | M41: 180.97 | N41: =F41*M41 -> 1621.8251 | O41: 179 | P41: =F41*O41 -> 1604.1703
A42: 7 | B42: =VLOOKUP(C42,Universe!$C$2:$E$201,3,FALSE) -> Information Technology | C42: META | D42: =VLOOKUP(C42,Universe!$C$2:$D$201,2,FALSE) -> Meta Platforms Inc. | E42: 0.0514 | F42: =($D$19*E42)/M42 -> 1.1377501 | M42: 488.46 | N42: =F42*M42 -> 555.74541 | O42: 436.61 | P42: =F42*O42 -> 496.75307
...
